2020-09-15 15:11:18,940 [django.request:230] [log:log_response] [WARNING] Not Found: /
2020-09-15 15:11:19,111 [django.request:230] [log:log_response] [WARNING] Not Found: /favicon.ico
2020-09-15 15:11:51,808 [django.request:230] [log:log_response] [ERROR] Internal Server Error: /phone/home
Traceback (most recent call last):
  File "E:\Python\Python36\lib\site-packages\django\core\handlers\exception.py", line 47, in inner
    response = get_response(request)
  File "E:\Python\Python36\lib\site-packages\django\core\handlers\base.py", line 179, in _get_response
    response = wrapped_callback(request, *callback_args, **callback_kwargs)
  File "E:\py\phone\phone_backstage\views.py", line 24, in home
    return render(request, {"country_list": country_list, "phone_list": phone_list, 'information_list': information_list})
  File "E:\Python\Python36\lib\site-packages\django\shortcuts.py", line 19, in render
    content = loader.render_to_string(template_name, context, request, using=using)
  File "E:\Python\Python36\lib\site-packages\django\template\loader.py", line 61, in render_to_string
    template = get_template(template_name, using=using)
  File "E:\Python\Python36\lib\site-packages\django\template\loader.py", line 15, in get_template
    return engine.get_template(template_name)
  File "E:\Python\Python36\lib\site-packages\django\template\backends\django.py", line 34, in get_template
    return Template(self.engine.get_template(template_name), self)
  File "E:\Python\Python36\lib\site-packages\django\template\engine.py", line 143, in get_template
    template, origin = self.find_template(template_name)
  File "E:\Python\Python36\lib\site-packages\django\template\engine.py", line 125, in find_template
    template = loader.get_template(name, skip=skip)
  File "E:\Python\Python36\lib\site-packages\django\template\loaders\base.py", line 18, in get_template
    for origin in self.get_template_sources(template_name):
  File "E:\Python\Python36\lib\site-packages\django\template\loaders\filesystem.py", line 36, in get_template_sources
    name = safe_join(template_dir, template_name)
  File "E:\Python\Python36\lib\site-packages\django\utils\_os.py", line 17, in safe_join
    final_path = abspath(join(base, *paths))
  File "E:\Python\Python36\lib\ntpath.py", line 115, in join
    genericpath._check_arg_types('join', path, *paths)
  File "E:\Python\Python36\lib\genericpath.py", line 149, in _check_arg_types
    (funcname, s.__class__.__name__)) from None
TypeError: join() argument must be str or bytes, not 'dict'
2020-09-15 15:13:07,805 [django.request:230] [log:log_response] [ERROR] Internal Server Error: /phone/home
Traceback (most recent call last):
  File "E:\Python\Python36\lib\site-packages\django\core\handlers\exception.py", line 47, in inner
    response = get_response(request)
  File "E:\Python\Python36\lib\site-packages\django\core\handlers\base.py", line 179, in _get_response
    response = wrapped_callback(request, *callback_args, **callback_kwargs)
  File "E:\py\phone\phone_backstage\views.py", line 24, in home
    return render(request,home.html, {"country_list": country_list, "phone_list": phone_list, 'information_list': information_list})
AttributeError: 'function' object has no attribute 'html'
