2020-09-02 17:30:20,227 [django.request:230] [log:log_response] [WARNING] Not Found: /
2020-09-02 17:30:29,524 [django.request:230] [log:log_response] [WARNING] Not Found: /phone
2020-09-02 17:30:36,894 [django.request:230] [log:log_response] [WARNING] Not Found: /phone/home
2020-09-02 17:32:20,609 [django.request:230] [log:log_response] [WARNING] Not Found: /phone/css/animate.css
2020-09-02 17:32:20,610 [django.request:230] [log:log_response] [WARNING] Not Found: /phone/js/bootstrap-paginator/bootstrap-paginator.js
2020-09-02 17:32:20,611 [django.request:230] [log:log_response] [WARNING] Not Found: /phone/css/mine.css
2020-09-02 17:32:20,612 [django.request:230] [log:log_response] [WARNING] Not Found: /phone/js/wow.min.js
2020-09-02 17:32:20,613 [django.request:230] [log:log_response] [WARNING] Not Found: /phone/js/jquery.singlePageNav.min.js
2020-09-02 17:32:20,614 [django.request:230] [log:log_response] [WARNING] Not Found: /phone/js/mine.js
2020-09-02 17:32:20,628 [django.request:230] [log:log_response] [WARNING] Not Found: /phone/js/bootstrap-paginator/bootstrap-paginator.js
2020-09-02 17:32:20,636 [django.request:230] [log:log_response] [WARNING] Not Found: /phone/js/jquery.singlePageNav.min.js
2020-09-02 17:32:20,643 [django.request:230] [log:log_response] [WARNING] Not Found: /phone/js/wow.min.js
2020-09-02 17:32:20,649 [django.request:230] [log:log_response] [WARNING] Not Found: /phone/js/mine.js
2020-09-02 17:35:03,427 [django.request:230] [log:log_response] [WARNING] Not Found: /favicon.ico
2020-09-02 17:38:48,635 [django.request:230] [log:log_response] [ERROR] Internal Server Error: /phone/home
Traceback (most recent call last):
  File "E:\Python\Python36\lib\site-packages\django\core\handlers\exception.py", line 47, in inner
    response = get_response(request)
  File "E:\Python\Python36\lib\site-packages\django\core\handlers\base.py", line 179, in _get_response
    response = wrapped_callback(request, *callback_args, **callback_kwargs)
  File "E:\py\phone\phone_backstage\views.py", line 14, in home
    data=dict.jion("")
AttributeError: 'QuerySet' object has no attribute 'jion'
2020-09-02 17:38:54,057 [django.request:230] [log:log_response] [ERROR] Internal Server Error: /phone/home
Traceback (most recent call last):
  File "E:\Python\Python36\lib\site-packages\django\core\handlers\exception.py", line 47, in inner
    response = get_response(request)
  File "E:\Python\Python36\lib\site-packages\django\core\handlers\base.py", line 179, in _get_response
    response = wrapped_callback(request, *callback_args, **callback_kwargs)
  File "E:\py\phone\phone_backstage\views.py", line 14, in home
    data=dict.jion("")
AttributeError: 'QuerySet' object has no attribute 'jion'
2020-09-02 17:38:54,090 [django.request:230] [log:log_response] [WARNING] Not Found: /favicon.ico
2020-09-02 17:41:07,761 [django.request:230] [log:log_response] [WARNING] Not Found: /favicon.ico
2020-09-02 17:41:45,539 [django.request:230] [log:log_response] [WARNING] Not Found: /favicon.ico
2020-09-02 17:48:55,733 [django.request:230] [log:log_response] [ERROR] Internal Server Error: /phone/home
Traceback (most recent call last):
  File "E:\Python\Python36\lib\site-packages\django\core\handlers\exception.py", line 47, in inner
    response = get_response(request)
  File "E:\Python\Python36\lib\site-packages\django\core\handlers\base.py", line 179, in _get_response
    response = wrapped_callback(request, *callback_args, **callback_kwargs)
  File "E:\py\phone\phone_backstage\views.py", line 22, in home
    return render(request, 'life.html', locals(), {"country_list": country_list})
  File "E:\Python\Python36\lib\site-packages\django\shortcuts.py", line 19, in render
    content = loader.render_to_string(template_name, context, request, using=using)
  File "E:\Python\Python36\lib\site-packages\django\template\loader.py", line 61, in render_to_string
    template = get_template(template_name, using=using)
  File "E:\Python\Python36\lib\site-packages\django\template\loader.py", line 19, in get_template
    raise TemplateDoesNotExist(template_name, chain=chain)
django.template.exceptions.TemplateDoesNotExist: life.html
2020-09-02 17:48:55,782 [django.request:230] [log:log_response] [WARNING] Not Found: /favicon.ico
2020-09-02 17:49:30,338 [django.request:230] [log:log_response] [ERROR] Internal Server Error: /phone/home
Traceback (most recent call last):
  File "E:\Python\Python36\lib\site-packages\django\core\handlers\exception.py", line 47, in inner
    response = get_response(request)
  File "E:\Python\Python36\lib\site-packages\django\core\handlers\base.py", line 179, in _get_response
    response = wrapped_callback(request, *callback_args, **callback_kwargs)
  File "E:\py\phone\phone_backstage\views.py", line 22, in home
    return render(request, locals(), {"country_list": country_list})
  File "E:\Python\Python36\lib\site-packages\django\shortcuts.py", line 19, in render
    content = loader.render_to_string(template_name, context, request, using=using)
  File "E:\Python\Python36\lib\site-packages\django\template\loader.py", line 61, in render_to_string
    template = get_template(template_name, using=using)
  File "E:\Python\Python36\lib\site-packages\django\template\loader.py", line 15, in get_template
    return engine.get_template(template_name)
  File "E:\Python\Python36\lib\site-packages\django\template\backends\django.py", line 34, in get_template
    return Template(self.engine.get_template(template_name), self)
  File "E:\Python\Python36\lib\site-packages\django\template\engine.py", line 143, in get_template
    template, origin = self.find_template(template_name)
  File "E:\Python\Python36\lib\site-packages\django\template\engine.py", line 125, in find_template
    template = loader.get_template(name, skip=skip)
  File "E:\Python\Python36\lib\site-packages\django\template\loaders\base.py", line 18, in get_template
    for origin in self.get_template_sources(template_name):
  File "E:\Python\Python36\lib\site-packages\django\template\loaders\filesystem.py", line 36, in get_template_sources
    name = safe_join(template_dir, template_name)
  File "E:\Python\Python36\lib\site-packages\django\utils\_os.py", line 17, in safe_join
    final_path = abspath(join(base, *paths))
  File "E:\Python\Python36\lib\ntpath.py", line 115, in join
    genericpath._check_arg_types('join', path, *paths)
  File "E:\Python\Python36\lib\genericpath.py", line 149, in _check_arg_types
    (funcname, s.__class__.__name__)) from None
TypeError: join() argument must be str or bytes, not 'dict'
2020-09-02 17:49:30,383 [django.request:230] [log:log_response] [WARNING] Not Found: /favicon.ico
2020-09-02 17:50:30,515 [django.request:230] [log:log_response] [ERROR] Internal Server Error: /phone/home
Traceback (most recent call last):
  File "E:\Python\Python36\lib\site-packages\django\core\handlers\exception.py", line 47, in inner
    response = get_response(request)
  File "E:\Python\Python36\lib\site-packages\django\core\handlers\base.py", line 179, in _get_response
    response = wrapped_callback(request, *callback_args, **callback_kwargs)
  File "E:\py\phone\phone_backstage\views.py", line 22, in home
    return render(request,{"country_list": country_list})
  File "E:\Python\Python36\lib\site-packages\django\shortcuts.py", line 19, in render
    content = loader.render_to_string(template_name, context, request, using=using)
  File "E:\Python\Python36\lib\site-packages\django\template\loader.py", line 61, in render_to_string
    template = get_template(template_name, using=using)
  File "E:\Python\Python36\lib\site-packages\django\template\loader.py", line 15, in get_template
    return engine.get_template(template_name)
  File "E:\Python\Python36\lib\site-packages\django\template\backends\django.py", line 34, in get_template
    return Template(self.engine.get_template(template_name), self)
  File "E:\Python\Python36\lib\site-packages\django\template\engine.py", line 143, in get_template
    template, origin = self.find_template(template_name)
  File "E:\Python\Python36\lib\site-packages\django\template\engine.py", line 125, in find_template
    template = loader.get_template(name, skip=skip)
  File "E:\Python\Python36\lib\site-packages\django\template\loaders\base.py", line 18, in get_template
    for origin in self.get_template_sources(template_name):
  File "E:\Python\Python36\lib\site-packages\django\template\loaders\filesystem.py", line 36, in get_template_sources
    name = safe_join(template_dir, template_name)
  File "E:\Python\Python36\lib\site-packages\django\utils\_os.py", line 17, in safe_join
    final_path = abspath(join(base, *paths))
  File "E:\Python\Python36\lib\ntpath.py", line 115, in join
    genericpath._check_arg_types('join', path, *paths)
  File "E:\Python\Python36\lib\genericpath.py", line 149, in _check_arg_types
    (funcname, s.__class__.__name__)) from None
TypeError: join() argument must be str or bytes, not 'dict'
2020-09-02 17:50:30,544 [django.request:230] [log:log_response] [WARNING] Not Found: /favicon.ico
2020-09-02 18:23:22,973 [django.request:230] [log:log_response] [ERROR] Internal Server Error: /phone/home
Traceback (most recent call last):
  File "E:\Python\Python36\lib\site-packages\django\core\handlers\exception.py", line 47, in inner
    response = get_response(request)
  File "E:\Python\Python36\lib\site-packages\django\utils\deprecation.py", line 116, in __call__
    response = self.process_response(request, response)
  File "E:\Python\Python36\lib\site-packages\django\middleware\common.py", line 106, in process_response
    if response.status_code == 404:
AttributeError: 'dict' object has no attribute 'status_code'
2020-09-02 18:27:19,431 [django.request:230] [log:log_response] [ERROR] Internal Server Error: /phone/home
Traceback (most recent call last):
  File "E:\Python\Python36\lib\site-packages\django\core\handlers\exception.py", line 47, in inner
    response = get_response(request)
  File "E:\Python\Python36\lib\site-packages\django\core\handlers\base.py", line 179, in _get_response
    response = wrapped_callback(request, *callback_args, **callback_kwargs)
  File "E:\py\phone\phone_backstage\views.py", line 23, in home
    return JsonResponse(country_list,phone_list,information_list, safe=False)
TypeError: __init__() got multiple values for argument 'safe'
2020-09-02 18:27:38,953 [django.request:230] [log:log_response] [ERROR] Internal Server Error: /phone/home
Traceback (most recent call last):
  File "E:\Python\Python36\lib\site-packages\django\core\handlers\exception.py", line 47, in inner
    response = get_response(request)
  File "E:\Python\Python36\lib\site-packages\django\core\handlers\base.py", line 179, in _get_response
    response = wrapped_callback(request, *callback_args, **callback_kwargs)
  File "E:\py\phone\phone_backstage\views.py", line 23, in home
    return JsonResponse(country_list,phone_list, safe=False)
  File "E:\Python\Python36\lib\site-packages\django\http\response.py", line 567, in __init__
    data = json.dumps(data, cls=encoder, **json_dumps_params)
  File "E:\Python\Python36\lib\json\__init__.py", line 238, in dumps
    **kw).encode(obj)
TypeError: 'list' object is not callable
